Workbook

Sheet Premisas
A1: BANCO CAPITAL S.A. | D1: PRESUPUESTO 2026
A2: PRINCIPALES PREMISAS PRESUPUESTARIAS | C2: meses | G2: # créditos vehículos
A4: Colocación cartera de crédito bruta | B4: 2026 | C4: 12 | D4: =SUM(F4:F8) -> 87703148 | E4: PRODUCTIVO | F4: =ProyCartCre!I6 -> 232150.98
A5: 2026: enero a diciembre | E5: CONSUMO | F5: =ProyCartCre!I7 -> 66796619 | G5: =F5/B115 -> 3710.9233
E6: MICROCREDITO | F6: =ProyCartCre!I8 -> 20410290 | G6: =F6/B115 -> 1133.905
E7: REFINANCIADA | F7: =ProyCartCre!I9 -> 110815.48
E8: REESTRUCTURADA | F8: =ProyCartCre!I10 -> 153271.99
A10: Recuperación cartera de crédito | B10: 2026 | C10: 12 | D10: =SUM(F10:F14) -> 15969548 | E10: PRODUCTIVO | F10: =ProyCartCre!E6+ProyCartCre!F6 -> 232150.98
A11: 2026: enero a diciembre | E11: CONSUMO | F11: =ProyCartCre!E7+ProyCartCre!F7 -> 12559019 | G11: =F11/B115 -> 697.72329
E12: MICROCREDITO | F12: =ProyCartCre!E8+ProyCartCre!F8 -> 2914290.5 | G12: =F12/B115 -> 161.90503
E13: REFINANCIADA | F13: =ProyCartCre!E9+ProyCartCre!F9 -> 110815.48
E14: REESTRUCTURADA | F14: =ProyCartCre!E10+ProyCartCre!F10 -> 153271.99
A16: Crecimiento cartera de crédito bruta | B16: 2026 | C16: 12 | D16: =SUM(F16:F20) -> 53733600 | E16: PRODUCTIVO | F16: =ProyCartCre!M6 -> 0
A17: 2026: enero a diciembre | E17: CONSUMO | F17: =ProyCartCre!M7 -> 36237600 | G17: =F17/B115 -> 2013.2
E18: MICROCREDITO | F18: =ProyCartCre!M8 -> 17496000 | G18: =F18/B115 -> 972
E19: REFINANCIADA | F19: =ProyCartCre!M9 -> 0
E20: REESTRUCTURADA | F20: =ProyCartCre!M10 -> 0
A22: Generación, venta y administración cartera | B22: 2026 | C22: 12 | D22: =F22 -> 18000000 | E22: CONSUMO | F22: =OVA!P6 -> 18000000 | G22: =F22/B115 -> 1000
A23: =A17 -> 2026: enero a diciembre | D23: =ROUND(D22/B115,0) -> 1000 | E23: # créditos
A24: Promedio mensual | D24: =D23/C22 -> 83.333333 | E24: # créditos
A25: Portafolio de inversiones | D25: Comportamiento en virtud del movimiento de fondos disponibles, precautelando mantener el suficiente activo líquido para las operaciones del Banco.
A26: Crecimiento depósitos a la vista | B26: 2023* | C26: 1 | D26: =F26/C26 -> 10000 | E26: promedio mensual | F26: 10000 | G26: anual
A27: Crecimiento depósitos a plazo | B27: 2023* | C27: 1 | D27: =F27/C27 -> -500000 | E27: promedio mensual | F27: -500000 | G27: anual
A29: Crecimiento depósitos a la vista | B29: 2026 | C29: 12 | D29: =F29/C29 -> 200000 | E29: promedio mensual | F29: 2400000 | G29: 12 meses
A30: Crecimiento depósitos a plazo | B30: 2026 | C30: 12 | D30: =F30/C30 -> 6196500 | E30: promedio mensual | F30: =B117*85% -> 74358000 | G30: 12 meses
A31: Recuperación de activos castigados (cartera y cuentas por cobrar) | B31: 2026 | C31: 12 | D31: =F31/C31 -> 12136.004 | E31: promedio mensual | F31: =SUM(BRhoriz!I194:P194) -> 145632.05 | G31: 12 meses
A32: Recuperación de activos castigados (cartera y cuentas por cobrar) | B32: 2026 | C32: 12 | D32: =F32/C32 -> 20833.333 | E32: promedio mensual | F32: 250000 | G32: 12 meses
A33: Reversión de provisiones (cartera, cuentas por cobrar, bienes recibidos en dación en pago) | B33: 2026 | C33: 12 | D33: =F33/C33 -> 24198.258 | E33: promedio mensual | F33: =SUM(BRhoriz!BE195:BJ195) -> 290379.1 | G33: 12 meses
A34: Inversión en sistemas y tecnología | B34: 2026 | C34: 12 | D34: 10000 | E34: promedio mensual | F34: =C34*D34 -> 120000 | G34: 12 meses
A35: Inversión en sistemas y tecnología | B35: 2026 | C35: 12 | D35: =F35/C35 -> 10000 | E35: promedio mensual | F35: 120000 | G35: 12 meses
A36: Inversión en nueva imagen del Banco | B36: 2026 | C36: 12 | D36: =F36/C36 -> 4166.6667 | E36: promedio mensual | F36: 50000 | G36: 12 meses
A37: Venta de casa recibida en dación en pago | B37: 2026 | D37: 0
A38: CAPITALIZACION | B38: 2026 | D38: 0
B39: 2023* - 2024
A41: Rendimiento inversiones disponibles para venta | B41: 2024 | C41: 0.0781 | D41: Rendimiento promedio ponderado Ene a Jun2024
A42: Rendimiento inversiones mantenidas hasta vcto | B42: 2024 | C42: 0.05 | D42: Rendimiento promedio ponderado proyectado
A43: Rendimiento cartera de crédito productivo | B43: 2024 | C43: =AVERAGE(BGhoriz!Q369:V369) -> 0.098611866 | D43: Tasa promedio ponderada Ene a Jun2024
A44: Rendimiento cartera de crédito consumo | B44: 2024 | C44: 0.15 | D44: Tasa estimada
A45: Rendimiento cartera de microcrédito | B45: 2024 | C45: 0.15 | D45: =D44 -> Tasa estimada
A46: Rendimiento cartera refinanciada | B46: 2024 | C46: =AVERAGE(BGhoriz!Q376:V376) -> 0.13468632 | D46: Tasa promedio ponderada Ene a Jun2024
...

Sheet EEFFun
B1: =Premisas!A1 -> BANCO CAPITAL S.A. | D1: ESTADOS FINANCIEROS A ÚLTIMO NIVEL | E1: ESTADOS FINANCIEROS A ÚLTIMO NIVEL | N1: ESTADOS FINANCIEROS A ÚLTIMO NIVEL
D2: 12 | E2: 1 | F2: 2 | G2: 3 | H2: 4 | I2: 5 | J2: 6 | K2: 7 | L2: 8 | M2: 9 | N2: 10 | O2: 11 | P2: 12 | Q2: 1 | R2: 2 | S2: 3 | T2: 4 | U2: 5 | V2: 6 | W2: 7 | X2: 8 | Y2: 9 | Z2: 10 | AA2: 11 | AB2: 12 | AC2: 1 | AD2: 2 | AE2: 3 | AF2: 4 | AG2: 5 | AH2: 6 | AI2: 7 | AJ2: 8 | AK2: 9 | AL2: 10 | AM2: 11 | AN2: 12 | AO2: 1 | AP2: 2 | AQ2: 3 | AR2: 4 | AS2: 5 | AT2: 6 | AU2: 7 | AV2: 8 | AW2: 9 | AX2: 10
A3: D | B3: CODIGO | C3: Cuenta | D3: 44561 | E3: 44592 | F3: 44620 | G3: 44651 | H3: 44681 | I3: 44712 | J3: 44742 | K3: 44773 | L3: 44804 | M3: 44834 | N3: 44865 | O3: 44895 | P3: 44926 | Q3: 44957 | R3: 44985 | S3: 45016 | T3: 45046 | U3: 45077 | V3: 45107 | W3: 45138 | X3: 45169 | Y3: 45199 | Z3: 45230 | AA3: 45260 | AB3: 45291 | AC3: 45322 | AD3: 45351 | AE3: 45382 | AF3: 45412 | AG3: 45443 | AH3: 45473 | AI3: 45504 | AJ3: 45535 | AK3: 45565 | AL3: 45596 | AM3: 45626 | AN3: 45657 | AO3: 45688 | AP3: 45716 | AQ3: 45747 | AR3: 45777 | AS3: 45808 | AT3: 45838 | AU3: 45869 | AV3: 45900 | AW3: 45930 | AX3: 45961
B4: 1 | C4: ACTIVOS | D4: 36785499 | E4: 36893446 | F4: 38348823 | G4: 38779119 | H4: 39117859 | I4: 39637060 | J4: 40115413 | K4: 40602162 | L4: 40166533 | M4: 42392654 | N4: 42463256 | O4: 42545573 | P4: 41871995 | Q4: 41428485 | R4: 41342572 | S4: 41608837 | T4: 41402927 | U4: 40814797 | V4: 39918747 | W4: 38859684 | X4: 38554650 | Y4: 38446164 | Z4: 39087530 | AA4: 38587003 | AB4: 38163618 | AC4: 38284842 | AD4: 37819571 | AE4: 38313322 | AF4: 38567040 | AG4: 41817124 | AH4: 47062540 | AI4: 47113341 | AJ4: 47711065 | AK4: 48144336 | AL4: 49311534 | AM4: 50621766 | AN4: 51800193 | AO4: 54248199 | AP4: 56369251 | AQ4: 61925193 | AR4: 59395369 | AS4: 61701051 | AT4: 63381053 | AU4: 66525948 | AV4: 68613984 | AW4: 69701630 | AX4: 72243574 | BF4: 1 | BG4: ACTIVOS | BH4: 47062540 | BI4: 1 | BJ4: ACTIVOS | BK4: 47113341
B5: 11 | C5: FONDOS DISPONIBLES | D5: 2686087 | E5: 2804100.2 | F5: 2695224.8 | G5: 2589769.2 | H5: 2923643.5 | I5: 2383972.8 | J5: 2540920.3 | K5: 2723411.2 | L5: 2143680.2 | M5: 3680138.1 | N5: 3077894.4 | O5: 2694462.4 | P5: 1875049.3 | Q5: 2157721.8 | R5: 1067075.5 | S5: 1371077.2 | T5: 1367417.2 | U5: 639585.39 | V5: 1015149.9 | W5: 1439298.4 | X5: 1405357.7 | Y5: 1420921.5 | Z5: 3468050.7 | AA5: 1823814 | AB5: 2030867.1 | AC5: 2478250.7 | AD5: 2693317.6 | AE5: 2647740 | AF5: 2607961.3 | AG5: 5634923.1 | AH5: 4254536.5 | AI5: 4099296 | AJ5: 4958217.3 | AK5: 4296254.5 | AL5: 4298604.7 | AM5: 3676654.6 | AN5: 4049699.8 | AO5: 5062709.1 | AP5: 5849402.1 | AQ5: 10155982 | AR5: 4699001.7 | AS5: 4336396.1 | AT5: 4550594.8 | AU5: 5911836.4 | AV5: 4866030.1 | AW5: 3430395.2 | AX5: 4340169 | BF5: 11 | BG5: FONDOS DISPONIBLES | BH5: 4254536.5 | BI5: 11 | BJ5: FONDOS DISPONIBLES | BK5: 4099296
B6: 1101 | C6: Caja | D6: 407928.36 | E6: 364748.68 | F6: 398771.2 | G6: 441259.02 | H6: 206209.45 | I6: 245002.16 | J6: 263087.73 | K6: 205228.55 | L6: 225069.1 | M6: 186808.61 | N6: 236209.4 | O6: 215810.59 | P6: 214026.13 | Q6: 277847.72 | R6: 286876.51 | S6: 204150.86 | T6: 160152.06 | U6: 131044.46 | V6: 176055.54 | W6: 198561.99 | X6: 195871.78 | Y6: 228922.32 | Z6: 283560.04 | AA6: 222619.25 | AB6: 208164.9 | AC6: 251432.59 | AD6: 240875.19 | AE6: 253033.42 | AF6: 187632.89 | AG6: 220439.2 | AH6: 310851.54 | AI6: 283281.66 | AJ6: 199494.72 | AK6: 278582.66 | AL6: 259551.5 | AM6: 199927.71 | AN6: 262062.05 | AO6: 277749.16 | AP6: 318505.87 | AQ6: 230466.86 | AR6: 234403.27 | AS6: 253245.71 | AT6: 310211.12 | AU6: 243391.61 | AV6: 197845.36 | AW6: 112996.15 | AX6: 163888.03 | BF6: 1101 | BG6: Caja | BH6: 310851.54 | BI6: 1101 | BJ6: Caja | BK6: 283281.66
B7: 110105 | C7: Efectivo | D7: 407228.36 | E7: 364048.68 | F7: 398071.2 | G7: 440559.02 | H7: 205509.45 | I7: 244302.16 | J7: 262387.73 | K7: 204528.55 | L7: 224369.1 | M7: 186108.61 | N7: 235509.4 | O7: 215110.59 | P7: 213326.13 | Q7: 277147.72 | R7: 286476.51 | S7: 203550.86 | T7: 159552.06 | U7: 130444.46 | V7: 175455.54 | W7: 197961.99 | X7: 195271.78 | Y7: 228322.32 | Z7: 282960.04 | AA7: 222019.25 | AB7: 207564.9 | AC7: 250832.59 | AD7: 240275.19 | AE7: 252433.42 | AF7: 187032.89 | AG7: 219839.2 | AH7: 310251.54 | AI7: 282681.66 | AJ7: 198894.72 | AK7: 277932.66 | AL7: 258901.5 | AM7: 199277.71 | AN7: 261412.05 | AO7: 277099.16 | AP7: 317855.87 | AQ7: 229816.86 | AR7: 233753.27 | AS7: 252595.71 | AT7: 309561.12 | AU7: 242741.61 | AV7: 197195.36 | AW7: 112346.15 | AX7: 163238.03 | BF7: 110105 | BG7: Efectivo | BH7: 310251.54 | BI7: 110105 | BJ7: Efectivo | BK7: 282681.66
B8: 11010505 | C8: EFECTIVO CAJEROS | D8: 228618.54 | E8: 185518.85 | F8: 225499.47 | G8: 267105.75 | H8: 197286.22 | I8: 236078.93 | J8: 254164.5 | K8: 196305.32 | L8: 216145.87 | M8: 177885.38 | N8: 227286.17 | O8: 215110.59 | P8: 213326.13 | Q8: 277147.72 | R8: 286476.51 | S8: 203550.86 | T8: 159552.06 | U8: 130444.46 | V8: 175455.54 | W8: 197961.99 | X8: 195271.78 | Y8: 228322.32 | Z8: 282960.04 | AA8: 222019.25 | AB8: 207564.9 | AC8: 250832.59 | AD8: 240275.19 | AE8: 252433.42 | AF8: 187032.89 | AG8: 219839.2 | AH8: 310251.54 | AI8: 282681.66 | AJ8: 198894.72 | AK8: 277932.66 | AL8: 258901.5 | AM8: 199277.71 | AN8: 261412.05 | AO8: 277099.16 | AP8: 317855.87 | AQ8: 229816.86 | AR8: 233753.27 | AS8: 252595.71 | AT8: 309561.12 | AU8: 242741.61 | AV8: 197195.36 | AW8: 112346.15 | AX8: 163238.03 | BF8: 11010505 | BG8: EFECTIVO CAJEROS | BH8: 310251.54 | BI8: 11010505 | BJ8: EFECTIVO CAJEROS | BK8: 282681.66
B9: 11010510 | C9: EFECTIVO SERVIPAGOS | D9: 178609.82 | E9: 178529.83 | F9: 172571.73 | G9: 173453.27 | H9: 8223.23 | I9: 8223.23 | J9: 8223.23 | K9: 8223.23 | L9: 8223.23 | M9: 8223.23 | N9: 8223.23 | AJ9: 0 | AK9: 0 | AL9: 0 | AM9: 0 | AN9: 0 | AO9: 0 | AP9: 0 | AQ9: 0 | AR9: 0 | AS9: 0 | AT9: 0 | AU9: 0 | AV9: 0 | AW9: 0 | AX9: 0
B10: 110110 | C10: Caja chica | D10: 700 | E10: 700 | F10: 700 | G10: 700 | H10: 700 | I10: 700 | J10: 700 | K10: 700 | L10: 700 | M10: 700 | N10: 700 | O10: 700 | P10: 700 | Q10: 700 | R10: 400 | S10: 600 | T10: 600 | U10: 600 | V10: 600 | W10: 600 | X10: 600 | Y10: 600 | Z10: 600 | AA10: 600 | AB10: 600 | AC10: 600 | AD10: 600 | AE10: 600 | AF10: 600 | AG10: 600 | AH10: 600 | AI10: 600 | AJ10: 600 | AK10: 650 | AL10: 650 | AM10: 650 | AN10: 650 | AO10: 650 | AP10: 650 | AQ10: 650 | AR10: 650 | AS10: 650 | AT10: 650 | AU10: 650 | AV10: 650 | AW10: 650 | AX10: 650 | BF10: 110110 | BG10: Caja chica | BH10: 600 | BI10: 110110 | BJ10: Caja chica | BK10: 600
B11: 1102 | C11: Depósitos para encaje | D11: 723166.33 | E11: 968383.13 | F11: 862945.84 | G11: 1459649.1 | H11: 1619818.6 | I11: 1689645.9 | J11: 1992147.8 | K11: 1923298.5 | L11: 1360725.8 | M11: 1805091.8 | N11: 2220619.2 | O11: 1756268.9 | P11: 1458459.1 | Q11: 1655874.6 | R11: 696024.36 | S11: 729617.53 | T11: 914088.16 | U11: 395720.74 | V11: 661246.05 | W11: 905886.15 | X11: 949534.49 | Y11: 1009525.2 | Z11: 2385698 | AA11: 1334167.7 | AB11: 1405746.8 | AC11: 1859123.1 | AD11: 2003168.1 | AE11: 2045474.5 | AF11: 1976303.9 | AG11: 3928148.2 | AH11: 3143751 | AI11: 2806504 | AJ11: 2163759.4 | AK11: 2242781.5 | AL11: 1709911.1 | AM11: 1638916.9 | AN11: 2070537.4 | AO11: 2642596.5 | AP11: 3166958.7 | AQ11: 6287760.7 | AR11: 2911875.5 | AS11: 2377694.2 | AT11: 2062558.2 | AU11: 2061537.2 | AV11: 1873146.7 | AW11: 2308812.5 | AX11: 1771523.1 | BF11: 1102 | BG11: Depósitos para encaje | BH11: 3143751 | BI11: 1102 | BJ11: Depósitos para encaje | BK11: 2806504
B12: 110205 | C12: Banco Central del Ecuador | D12: 723166.33 | E12: 968383.13 | F12: 862945.84 | G12: 1766788.9 | H12: 1619818.6 | I12: 1689645.9 | J12: 1992147.8 | K12: 1923298.5 | L12: 1360725.8 | M12: 1805091.8 | N12: 2220619.2 | O12: 1756268.9 | P12: 1458459.1 | Q12: 1655874.6 | R12: 696024.36 | S12: 729617.53 | T12: 914088.16 | U12: 395720.74 | V12: 661246.05 | W12: 905886.15 | X12: 949534.49 | Y12: 1009525.2 | Z12: 2385698 | AA12: 1334167.7 | AB12: 1405746.8 | AC12: 1859123.1 | AD12: 2003168.1 | AE12: 2045474.5 | AF12: 1976303.9 | AG12: 3928148.2 | AH12: 3143751 | AI12: 2806504 | AJ12: 2163759.4 | AK12: 2242781.5 | AL12: 1709911.1 | AM12: 1638916.9 | AN12: 2070537.4 | AO12: 2642596.5 | AP12: 3166958.7 | AQ12: 6287760.7 | AR12: 2911875.5 | AS12: 2377694.2 | AT12: 2062558.2 | AU12: 2061537.2 | AV12: 1873146.7 | AW12: 2308812.5 | AX12: 1771523.1 | BF12: 110205 | BG12: Banco Central del Ecuador | BH12: 3143751 | BI12: 110205 | BJ12: Banco Central del Ecuador | BK12: 2806504
B13: 1103 | C13: Bancos y otras instituciones financieras | D13: 1506823.3 | E13: 1401397 | F13: 1412256.6 | G13: 656553.18 | H13: 1015569.6 | I13: 438283.88 | J13: 210269.42 | K13: 549386.81 | L13: 447251.88 | M13: 1324072.7 | N13: 489999.22 | O13: 536468.17 | P13: 158169.61 | Q13: 195182.12 | R13: 71708.75 | S13: 422965.87 | T13: 281591.29 | U13: 98347.3 | V13: 169766.14 | W13: 318895.57 | X13: 232485.38 | Y13: 167037.38 | Z13: 694592.63 | AA13: 235800.14 | AB13: 244049.01 | AC13: 348962.61 | AD13: 389760.87 | AE13: 336932.08 | AF13: 435474.52 | AG13: 1455911 | AH13: 779934.02 | AI13: 1007131.2 | AJ13: 2594573.1 | AK13: 1758795.6 | AL13: 2319909.5 | AM13: 1832736.2 | AN13: 1675024.8 | AO13: 2062363.4 | AP13: 2263741.4 | AQ13: 3621125.2 | AR13: 1503949.6 | AS13: 1590635.2 | AT13: 2021103.7 | AU13: 3579970.1 | AV13: 2658908 | AW13: 908586.61 | AX13: 2378842.1 | BF13: 1103 | BG13: Bancos y otras instituciones financieras | BH13: 779934.02 | BI13: 1103 | BJ13: Bancos y otras instituciones financieras | BK13: 1007131.2
B14: 110310 | C14: Bancos e instituciones financieras locales | D14: 1492860.1 | E14: 1387433.8 | F14: 1398292.9 | G14: 642589.49 | H14: 1001605.9 | I14: 424320.19 | J14: 196305.73 | K14: 535423.12 | L14: 433288.19 | M14: 1310109 | N14: 481279.12 | O14: 527748.07 | P14: 149402.61 | Q14: 186391.8 | R14: 62918.43 | S14: 414175.55 | T14: 272800.97 | U14: 89556.98 | V14: 160975.82 | W14: 310105.25 | X14: 223695.06 | Y14: 158247.06 | Z14: 685718.35 | AA14: 226925.86 | AB14: 235174.73 | AC14: 340088.33 | AD14: 380886.59 | AE14: 328057.8 | AF14: 426600.24 | AG14: 1447036.8 | AH14: 771059.74 | AI14: 998256.87 | AJ14: 2585698.8 | AK14: 1749921.3 | AL14: 2311035.3 | AM14: 1823861.9 | AN14: 1666150.5 | AO14: 2053489.2 | AP14: 2254867.1 | AQ14: 3612250.9 | AR14: 1495075.4 | AS14: 1581760.9 | AT14: 2012229.4 | AU14: 3571095.8 | AV14: 2650033.7 | AW14: 899712.33 | AX14: 2369967.9 | BF14: 110310 | BG14: Bancos e instituciones financieras locales | BH14: 771059.74 | BI14: 110310 | BJ14: Bancos e instituciones financieras locales | BK14: 998256.87
B15: 110315 | C15: Bancos e instituciones financieras del exterior | D15: 13963.15 | E15: 13963.15 | F15: 13963.69 | G15: 13963.69 | H15: 13963.69 | I15: 13963.69 | J15: 13963.69 | K15: 13963.69 | L15: 13963.69 | M15: 13963.69 | N15: 8720.1 | O15: 8720.1 | P15: 8767 | Q15: 8790.32 | R15: 8790.32 | S15: 8790.32 | T15: 8790.32 | U15: 8790.32 | V15: 8790.32 | W15: 8790.32 | X15: 8790.32 | Y15: 8790.32 | Z15: 8874.28 | AA15: 8874.28 | AB15: 8874.28 | AC15: 8874.28 | AD15: 8874.28 | AE15: 8874.28 | AF15: 8874.28 | AG15: 8874.28 | AH15: 8874.28 | AI15: 8874.28 | AJ15: 8874.28 | AK15: 8874.28 | AL15: 8874.28 | AM15: 8874.28 | AN15: 8874.28 | AO15: 8874.28 | AP15: 8874.28 | AQ15: 8874.28 | AR15: 8874.28 | AS15: 8874.28 | AT15: 8874.28 | AU15: 8874.28 | AV15: 8874.28 | AW15: 8874.28 | AX15: 8874.28 | BF15: 110315 | BG15: Bancos e instituciones financieras del exterior | BH15: 8874.28 | BI15: 110315 | BJ15: Bancos e instituciones financieras del exterior | BK15: 8874.28
B16: 1104 | C16: Efectos de cobro inmediato | D16: 48169.06 | E16: 69571.44 | F16: 21251.11 | G16: 32307.88 | H16: 82045.86 | I16: 11040.81 | J16: 75415.34 | K16: 45497.37 | L16: 110633.45 | M16: 364165.07 | N16: 131066.59 | O16: 185914.73 | P16: 44394.42 | Q16: 28817.37 | R16: 12465.85 | S16: 14342.96 | T16: 11585.67 | U16: 14472.89 | V16: 8082.17 | W16: 15954.67 | X16: 27466.02 | Y16: 15436.64 | Z16: 104200 | AA16: 31226.91 | AB16: 172906.43 | AC16: 18732.34 | AD16: 59513.5 | AE16: 12300 | AF16: 8550 | AG16: 30424.61 | AH16: 20000 | AI16: 2379.15 | AJ16: 390.07 | AK16: 16094.73 | AL16: 9232.53 | AM16: 5073.8 | AN16: 42075.6 | AO16: 80000 | AP16: 100196.19 | AQ16: 16629.5 | AR16: 48773.38 | AS16: 114820.99 | AT16: 156721.71 | AU16: 26937.47 | AV16: 136130.02 | AW16: 100000 | AX16: 25915.8 | BF16: 1104 | BG16: Efectos de cobro inmediato | BH16: 20000 | BI16: 1104 | BJ16: Efectos de cobro inmediato | BK16: 2379.15
B17: 110405 | C17: EFECTOS INGRESADOS A CAJA | D17: 2004.54 | E17: 2004.54 | F17: 2004.54 | G17: 2004.54 | H17: 2004.54 | I17: 2004.54 | J17: 2004.54 | AJ17: 0 | AK17: 0 | AL17: 0 | AM17: 0 | AN17: 0 | AO17: 0 | AP17: 0 | AQ17: 0 | AR17: 0 | AS17: 0 | AT17: 0 | AU17: 0 | AV17: 0 | AW17: 0 | AX17: 0
B18: 110410 | C18: VALORES ENVIADOS A CÁMARA DE COMPENSACIÓN | D18: 46164.52 | E18: 67566.9 | F18: 19246.57 | G18: 30303.34 | H18: 80041.32 | I18: 9036.27 | J18: 73410.8 | K18: 45497.37 | L18: 110633.45 | M18: 364165.07 | N18: 131066.59 | O18: 185914.73 | P18: 44394.42 | Q18: 28817.37 | R18: 12465.85 | S18: 14342.96 | T18: 11585.67 | U18: 14472.89 | V18: 8082.17 | W18: 15954.67 | X18: 27466.02 | Y18: 15436.64 | Z18: 104200 | AA18: 31226.91 | AB18: 172906.43 | AC18: 18732.34 | AD18: 59513.5 | AE18: 12300 | AF18: 8550 | AG18: 30424.61 | AH18: 20000 | AI18: 2379.15 | AJ18: 390.07 | AK18: 16094.73 | AL18: 9232.53 | AM18: 2798.76 | AN18: 25000 | AO18: 80000 | AP18: 86700.69 | AQ18: 3134 | AR18: 48773.38 | AS18: 114420.99 | AT18: 156721.71 | AU18: 26937.47 | AV18: 136130.02 | AW18: 100000 | AX18: 25915.8 | BF18: 110410 | BG18: VALORES ENVIADOS A CÁMARA DE COMPENSACIÓN | BH18: 20000 | BI18: 110410 | BJ18: VALORES ENVIADOS A CÁMARA DE COMPENSACIÓN | BK18: 2379.15
B19: 13 | C19: INVERSIONES | D19: 5705796.3 | E19: 5110401.8 | F19: 5706550.3 | G19: 4642393.1 | H19: 4135535.7 | I19: 4208787.1 | J19: 4208726 | K19: 4102857.7 | L19: 4109775.8 | M19: 5136909.8 | N19: 5414946.9 | O19: 5432407.7 | P19: 4569816.5 | Q19: 4396213.9 | R19: 4304281.3 | S19: 3882342.1 | T19: 3717634.7 | U19: 3705733.6 | V19: 3355464.7 | W19: 2765240.9 | X19: 2749371.4 | Y19: 2738719.7 | Z19: 2140533.1 | AA19: 3155413.9 | AB19: 5472959.3 | AC19: 5593231.5 | AD19: 5619865.4 | AE19: 5768860.9 | AF19: 5990435 | AG19: 6535690.2 | AH19: 6902967.2 | AI19: 6494256.5 | AJ19: 6306447.7 | AK19: 6725858.3 | AL19: 7257820.6 | AM19: 7421635.4 | AN19: 7437172.5 | AO19: 8068951.5 | AP19: 8156070.3 | AQ19: 8475496.9 | AR19: 8588335.1 | AS19: 8657652.1 | AT19: 7871172 | AU19: 8339019 | AV19: 8332154.9 | AW19: 8240933.2 | AX19: 6909362.7 | BF19: 13 | BG19: INVERSIONES | BH19: 6902967.2 | BI19: 13 | BJ19: INVERSIONES | BK19: 6494256.5
B20: 1303 | C20: Disponibles para la venta de entidades del sector privado | D20: 2270718.8 | E20: 1476474.9 | F20: 1981443.3 | G20: 984132.65 | H20: 613516.93 | I20: 636788.11 | J20: 685266.72 | K20: 587236.61 | L20: 590288.39 | M20: 1567215.6 | N20: 1576222.8 | O20: 1735420.4 | P20: 873535.46 | Q20: 675506.01 | R20: 571537.73 | S20: 159326.22 | AA20: 989738.94 | AB20: 3293488 | AC20: 3203322 | AD20: 3224550.5 | AE20: 3286443 | AF20: 3319558.5 | AG20: 3643661.2 | AH20: 3501862.1 | AI20: 2930627.8 | AJ20: 2951359.5 | AK20: 3210364 | AL20: 3747715 | AM20: 3772843.1 | AN20: 3736839.7 | AO20: 4047091.1 | AP20: 4071250.8 | AQ20: 4325367.7 | AR20: 4170377.3 | AS20: 4176153.7 | AT20: 3394593.6 | AU20: 3638363.8 | AV20: 3524422.2 | AW20: 3244758.1 | AX20: 1333972.4 | BF20: 1303 | BG20: Disponibles para la venta de entidades del sector | BH20: 3501862.1 | BI20: 1303 | BJ20: Disponibles para la venta de entidades del sector | BK20: 2930627.8
B21: 130305 | C21: De 1 a 30 días | D21: 2262351.5 | E21: 1468046.6 | F21: 1471590.6 | G21: 473768.42 | H21: 404292.91 | I21: 202827.73 | J21: 101249.93 | K21: 432278.99 | L21: 330519.45 | N21: 153358.33 | O21: 966698.78 | P21: 202034.17 | Q21: 107021.85 | R21: 413146.67 | S21: 159326.22 | AB21: 93029.17 | AD21: 45140.92 | AE21: 94083.53 | AG21: 147355.87 | AH21: 549108.12 | AJ21: 45311.4 | AK21: 94104.07 | AL21: 50014.59 | AM21: 401448.89 | AN21: 752988.15 | AO21: 180958.11 | AP21: 538713.65 | AQ21: 1184575.4 | AR21: 789389 | AS21: 836215.76 | AT21: 767890.25 | AU21: 393345.64 | AV21: 1356503.6 | AW21: 1421996.4 | AX21: 823359.35 | BF21: 130305 | BG21: De 1 a 30 días | BH21: 549108.12
B22: 130310 | C22: De 31 a 90 días | F22: 300694.44 | G22: 403193.75 | H22: 101426.39 | I22: 427653.57 | J22: 429928.36 | L22: 151706.25 | M22: 807441.81 | N22: 708954.67 | O22: 206998.86 | P22: 514890.08 | Q22: 568484.16 | R22: 158391.06 | AA22: 44540.01 | AB22: 44475.87 | AC22: 137670.47 | AD22: 93446.72 | AE22: 145324.17 | AF22: 389401.73 | AG22: 545416.85 | AH22: 44624.19 | AI22: 137818.79 | AJ22: 0 | AK22: 0 | AL22: 0 | AM22: 0 | AN22: 0 | AO22: 0 | AP22: 0 | AQ22: 0 | AR22: 0 | AS22: 0 | AT22: 0 | AU22: 0 | AV22: 0 | AW22: 0 | AX22: 0 | BF22: 130310 | BG22: De 31 a 90 días | BH22: 44624.19 | BI22: 130310 | BJ22: De 31 a 90 días | BK22: 137818.79
B23: 130315 | C23: De 91 a 180 días | F23: 200675 | G23: 100952.78 | H23: 101536.11 | J23: 154088.43 | K23: 154957.62 | L23: 108062.69 | M23: 605937.95 | N23: 713909.79 | O23: 561722.71 | P23: 156611.21 | AA23: 44540.01 | AB23: 149958.83 | AC23: 137670.47 | AD23: 138587.64 | AE23: 138718.81 | AF23: 137798.26 | AG23: 138778.69 | AH23: 138707.72 | AI23: 137818.79 | AJ23: 0 | AK23: 0 | AL23: 0 | AM23: 0 | AN23: 0 | AO23: 0 | AP23: 0 | AQ23: 0 | AR23: 0 | AS23: 0 | AT23: 0 | AU23: 0 | AV23: 0 | AW23: 0 | AX23: 0 | BF23: 130315 | BG23: De 91 a 180 días | BH23: 138707.72 | BI23: 130315 | BJ23: De 91 a 180 días | BK23: 137818.79
B24: 130320 | C24: De 181 a 360 días | D24: 8367.33 | E24: 8428.22 | F24: 8483.29 | G24: 6217.7 | H24: 6261.52 | I24: 6306.81 | M24: 153835.86 | AA24: 89080.03 | AB24: 262556.32 | AC24: 275340.96 | AD24: 277175.29 | AE24: 277437.62 | AF24: 275596.52 | AG24: 277557.38 | AH24: 277415.43 | AI24: 275637.57 | AJ24: 277598.41 | AK24: 277461.81 | AL24: 275649.22 | AM24: 277552.97 | AN24: 277478.68 | AO24: 275659.74 | AP24: 277430.82 | AQ24: 277396.57 | AR24: 179949.74 | AS24: 181254.44 | AT24: 225610.63 | AU24: 214290.17 | AV24: 110414.95 | AW24: 111142.79 | AX24: 0 | BF24: 130320 | BG24: De 181 a 360 días | BH24: 277415.43 | BI24: 130320 | BJ24: De 181 a 360 días | BK24: 275637.57
B25: 130325 | C25: De más de 360 días | AA25: 811578.89 | AB25: 2743467.8 | AC25: 2652640.1 | AD25: 2670199.9 | AE25: 2630878.8 | AF25: 2516762 | AG25: 2534552.4 | AH25: 2492006.6 | AI25: 2379352.6 | AJ25: 2396162.7 | AK25: 2353721.6 | AL25: 2241608.2 | AM25: 2256966.2 | AN25: 2215090.7 | AO25: 2103846.3 | AP25: 2117258.5 | AQ25: 2075655.9 | AR25: 2022468.7 | AS25: 2021779.2 | AT25: 1639782.5 | AU25: 1511810.1 | AV25: 638778.97 | AW25: 642989.8 | AX25: 0 | BF25: 130325 | BG25: De más de 360 días | BH25: 2492006.6 | BI25: 130325 | BJ25: De más de 360 días | BK25: 2379352.6
B26: 1304 | C26: Disponibles para la venta del estado o de entidades sector público | D26: 1312196.2 | E26: 1422005.2 | F26: 1421784.6 | G26: 1312657.6 | H26: 1146094.3 | I26: 1164864.9 | J26: 1114805.9 | K26: 1116018.4 | L26: 1113708 | M26: 1154693.4 | N26: 1356530.8 | O26: 1198346.7 | P26: 1195356.7 | Q26: 1198541.3 | R26: 1201417.8 | S26: 1204602.4 | T26: 1207684.3 | U26: 1210868.9 | V26: 892037.29 | W26: 332131.87 | X26: 332972.21 | Y26: 333785.44 | Z26: 119572.78 | AA26: 119864.07 | AB26: 119506.7 | AC26: 318411.53 | AD26: 319022.94 | AE26: 418285.24 | AF26: 597604.13 | AG26: 798487.53 | AH26: 1243123.1 | AI26: 1243953.3 | AJ26: 1244880.1 | AK26: 1243156 | AL26: 1243987.4 | AM26: 1344563.5 | AN26: 1345585.8 | AO26: 1543183.9 | AP26: 1543770.5 | AQ26: 1544918.5 | AR26: 1691354.8 | AS26: 1692858.9 | AT26: 1694604.5 | AU26: 1850971.1 | AV26: 1852904.2 | AW26: 1954783.7 | AX26: 2050883.4 | BF26: 1304 | BG26: Disponibles para la venta del estado o de entidade | BH26: 1243123.1 | BI26: 1304 | BJ26: Disponibles para la venta del estado o de entidade | BK26: 1243953.3
B27: 130405 | C27: De 1 a 30 días | D27: 413105.51 | E27: 641724.91 | F27: 500231.41 | G27: 313551.54 | H27: 610924.96 | I27: 390716.89 | J27: 145763.67 | K27: 630985.08 | L27: 169881.12 | M27: 145773.33 | N27: 801294.8 | O27: 209836.68 | Y27: 109768.59 | AA27: 119864.07 | AD27: 119906.67 | AE27: 99894.01 | AF27: 99889.73 | AG27: 219795.27 | AH27: 279830.46 | AI27: 300834.71 | AJ27: 666144.12 | AK27: 279852.86 | AL27: 300856.04 | AM27: 284766.08 | AN27: 662003 | AO27: 401072.72 | AP27: 284743.29 | AQ27: 861728.33 | AR27: 401013.1 | AS27: 284688.81 | AT27: 1011504.5 | AU27: 401015.27 | AV27: 284715.8 | AW27: 1171879.3 | AX27: 401046.15 | BF27: 130405 | BG27: De 1 a 30 días | BH27: 279830.46 | BI27: 130405 | BJ27: De 1 a 30 días | BK27: 300834.71
B28: 130410 | C28: De 31 a 90 días | D28: 899090.65 | E28: 571456.1 | F28: 921553.14 | G28: 999106.02 | H28: 535169.31 | I28: 774147.99 | J28: 969042.2 | K28: 485033.36 | L28: 774195.56 | M28: 1008920.1 | N28: 209486.71 | W28: 109225.67 | X28: 213991.71 | Y28: 224016.85 | Z28: 119572.78 | AB28: 119506.7 | AC28: 219183.41 | AD28: 199116.27 | AE28: 318391.23 | AF28: 497714.4 | AG28: 578692.26 | AH28: 963292.63 | AI28: 943118.62 | AJ28: 578736.01 | AK28: 583570.62 | AL28: 943131.34 | AM28: 1059797.5 | AN28: 683582.81 | AO28: 1142111.2 | AP28: 1259027.2 | AQ28: 683190.2 | AR28: 1091187.6 | AS28: 1408170.1 | AT28: 683100 | AU28: 1449955.9 | AV28: 1568188.4 | AW28: 782904.38 | AX28: 1649837.3 | BF28: 130410 | BG28: De 31 a 90 días | BH28: 963292.63 | BI28: 130410 | BJ28: De 31 a 90 días | BK28: 943118.62
B29: 130415 | C29: De 91 a 180 días | E29: 208824.15 | L29: 169631.36 | T29: 459793.53 | U29: 1004114.3 | V29: 892037.29 | W29: 222906.2 | X29: 118980.5 | AC29: 99228.12 | AO29: 0 | AP29: 0 | AQ29: 0 | AR29: 0 | AS29: 0 | AT29: 0 | AU29: 0 | AV29: 0 | AW29: 0 | AX29: 0
B30: 130420 | C30: De 181 a 360 días | N30: 345749.31 | O30: 988510.01 | P30: 1195356.7 | Q30: 1198541.3 | R30: 1201417.8 | S30: 1204602.4 | T30: 747890.73 | U30: 206754.59 | AO30: 0 | AP30: 0 | AQ30: 0 | AR30: 0 | AS30: 0 | AT30: 0 | AU30: 0 | AV30: 0 | AW30: 0 | AX30: 0
B31: 1305 | C31: Mantenidas hasta el vencimiento de entidades sector privado | AO31: 0 | AP31: 0 | AQ31: 0 | AR31: 0 | AS31: 0 | AT31: 0 | AU31: 0 | AV31: 0 | AW31: 0 | AX31: 0
B32: 130505 | C32: De 1 a 30 días | AO32: 0 | AP32: 0 | AQ32: 0 | AR32: 0 | AS32: 0 | AT32: 0 | AU32: 0 | AV32: 0 | AW32: 0 | AX32: 0
B33: 130510 | C33: De 31 a 90 días | AO33: 0 | AP33: 0 | AQ33: 0 | AR33: 0 | AS33: 0 | AT33: 0 | AU33: 0 | AV33: 0 | AW33: 0 | AX33: 0
B34: 1306 | C34: Mantenidas hasta el vencimiento del estado o de en | D34: 1760226.9 | E34: 1849267.3 | F34: 1940708.2 | G34: 1982968.5 | H34: 2013310.3 | I34: 2044499.8 | J34: 2046019.1 | K34: 2036968.3 | L34: 2043124.9 | M34: 2052346.3 | N34: 2119538.8 | O34: 2135986.1 | P34: 2138249.7 | Q34: 2159492 | R34: 2168711.6 | S34: 2155819.4 | T34: 2147356.4 | U34: 2132310.9 | V34: 2100873.6 | W34: 2070535.1 | X34: 2053825.3 | Y34: 2041836.7 | Z34: 2020960.4 | AA34: 2045810.9 | AB34: 2059964.6 | AC34: 2071498 | AD34: 2076291.9 | AE34: 2064132.7 | AF34: 2073272.3 | AG34: 2093541.4 | AH34: 2157982 | AI34: 2319675.4 | AJ34: 2110208.1 | AK34: 2272338.3 | AL34: 2266118.2 | AM34: 2304228.7 | AN34: 2344713.5 | AO34: 2468593.4 | AP34: 2530921.2 | AQ34: 2595033.4 | AR34: 2716377.8 | AS34: 2778364.8 | AT34: 2771651.3 | AU34: 2839311.9 | AV34: 2944406.9 | AW34: 3030921.8 | AX34: 3086341.5 | BF34: 1306 | BG34: Mantenidas hasta el vencimiento del estado o de en | BH34: 2157982 | BI34: 1306 | BJ34: Mantenidas hasta el vencimiento del estado o de en | BK34: 2319675.4
B35: 130615 | C35: De 91 a 180 días | D35: 1760226.9 | E35: 1849267.3 | F35: 1940708.2 | G35: 1982968.5 | H35: 2013310.3 | I35: 2044499.8 | J35: 2046019.1 | K35: 2036968.3 | L35: 2043124.9 | M35: 2052346.3 | N35: 2119538.8 | O35: 2135986.1 | P35: 2138249.7 | Q35: 2159492 | R35: 2168711.6 | S35: 2155819.4 | T35: 2147356.4 | U35: 2132310.9 | V35: 2100873.6 | W35: 2070535.1 | X35: 2053825.3 | Y35: 2041836.7 | Z35: 2020960.4 | AA35: 2045810.9 | AB35: 2059964.6 | AC35: 2071498 | AD35: 2076291.9 | AE35: 2064132.7 | AF35: 2073272.3 | AG35: 2093541.4 | AH35: 2157982 | AI35: 2319675.4 | AJ35: 2110208.1 | AK35: 2272338.3 | AL35: 2266118.2 | AM35: 2304228.7 | AN35: 2344713.5 | AO35: 2468593.4 | AP35: 2530921.2 | AQ35: 2595033.4 | AR35: 2716377.8 | AS35: 2778364.8 | AT35: 2771651.3 | AU35: 2839311.9 | AV35: 2944406.9 | AW35: 3030921.8 | AX35: 3086341.5 | BF35: 130615 | BG35: De 91 a 180 días | BH35: 2157982 | BI35: 130615 | BJ35: De 91 a 180 días | BK35: 2319675.4
B36: 1307 | C36: De disponibilidad restringida | D36: 362654.49 | E36: 362654.49 | F36: 362614.21 | G36: 362634.35 | H36: 362614.21 | I36: 362634.35 | J36: 362634.35 | K36: 362634.35 | L36: 362654.49 | M36: 362654.49 | N36: 362654.49 | O36: 362654.49 | P36: 362674.63 | Q36: 362674.63 | R36: 362614.21 | S36: 362594.07 | T36: 362594.07 | U36: 362553.8 | V36: 362553.8 | W36: 362573.93 | X36: 362573.93 | Y36: 363097.54 | AN36: 10033.54 | AO36: 10083.06 | AP36: 10127.78 | AQ36: 10177.29 | AR36: 10225.21 | AS36: 10274.72 | AT36: 10322.64 | AU36: 10372.15 | AV36: 10421.67 | AW36: 10469.58 | AX36: 438165.38
B37: 130710 | C37: Depósitos sujetos a restricción | D37: 362654.49 | E37: 362654.49 | F37: 362614.21 | G37: 362634.35 | H37: 362614.21 | I37: 362634.35 | J37: 362634.35 | K37: 362634.35 | L37: 362654.49 | M37: 362654.49 | N37: 362654.49 | O37: 362654.49 | P37: 362674.63 | Q37: 362674.63 | R37: 362614.21 | S37: 362594.07 | T37: 362594.07 | U37: 362553.8 | V37: 362553.8 | W37: 362573.93 | X37: 362573.93 | Y37: 363097.54 | AN37: 10033.54 | AO37: 10083.06 | AP37: 10127.78 | AQ37: 10177.29 | AR37: 10225.21 | AS37: 10274.72 | AT37: 10322.64 | AU37: 10372.15 | AV37: 10421.67 | AW37: 10469.58 | AX37: 10519.1
B38: 14 | C38: CARTERA DE CREDITOS | D38: 16941057 | E38: 17465919 | F38: 18395321 | G38: 19854931 | H38: 20338206 | I38: 21390769 | J38: 21843896 | K38: 22248486 | L38: 22403326 | M38: 22142781 | N38: 22483243 | O38: 22912017 | P38: 23772499 | Q38: 23269792 | R38: 24359372 | S38: 24821532 | T38: 24750622 | U38: 24906664 | V38: 24123481 | W38: 23259505 | X38: 23029410 | Y38: 22965420 | Z38: 22165634 | AA38: 22203438 | AB38: 19180364 | AC38: 18773966 | AD38: 18008447 | AE38: 18365493 | AF38: 18486105 | AG38: 18109430 | AH38: 24318701 | AI38: 24732960 | AJ38: 24692896 | AK38: 24847676 | AL38: 25536075 | AM38: 24396647 | AN38: 25299258 | AO38: 26164723 | AP38: 27274081 | AQ38: 28308348 | AR38: 31045993 | AS38: 32984678 | AT38: 35797577 | AU38: 36874866 | AV38: 39485583 | AW38: 41678361 | AX38: 45825231 | BF38: 14 | BG38: CARTERA DE CREDITOS | BH38: 24318701 | BI38: 14 | BJ38: CARTERA DE CREDITOS | BK38: 24732960
C39: CARTERA DE CREDITOS BRUTA | D39: =SUM(D40:D49) -> 18527280 | E39: =SUM(E40:E49) -> 19008396 | F39: =SUM(F40:F49) -> 19834142 | G39: =SUM(G40:G49) -> 21296414 | H39: =SUM(H40:H49) -> 21815268 | I39: =SUM(I40:I49) -> 22899243 | J39: =SUM(J40:J49) -> 23375519 | K39: =SUM(K40:K49) -> 23771584 | ... AX39: =SUM(AX40:AX49) -> 46916087
C40: PRODUCTIVO | D40: =D53+D95+D137 -> 640031.74 | E40: =E53+E95+E137 -> 589612 | F40: =F53+F95+F137 -> 921670.45 | G40: =G53+G95+G137 -> 1491384.3 | H40: =H53+H95+H137 -> 1543212.4 | I40: =I53+I95+I137 -> 1836803.3 | J40: =J53+J95+J137 -> 1779345 | K40: =K53+K95+K137 -> 1782985.1 | ... AX40: =AX53+AX95+AX137 -> 643955.82
...

Sheet BGhoriz
B1: =Premisas!A1 -> BANCO CAPITAL S.A.
B2: PRESUPUESTOS 2024 | D2: EJECUTADO | E2: EJECUTADO | F2: EJECUTADO | G2: EJECUTADO | H2: EJECUTADO | I2: EJECUTADO | J2: EJECUTADO | K2: EJECUTADO | L2: EJECUTADO | M2: EJECUTADO | N2: EJECUTADO | O2: EJECUTADO | P2: EJECUTADO | Q2: EJECUTADO | R2: EJECUTADO | S2: EJECUTADO | T2: EJECUTADO | U2: EJECUTADO | V2: EJECUTADO | W2: EJECUTADO | X2: EJECUTADO | Y2: EJECUTADO | Z2: EJECUTADO | AA2: EJECUTADO | AB2: EJECUTADO | AC2: EJECUTADO | AD2: EJECUTADO | AE2: EJECUTADO | AF2: EJECUTADO | AG2: EJECUTADO | AH2: EJECUTADO | AI2: EJECUTADO | AJ2: EJECUTADO | AK2: EJECUTADO | AL2: EJECUTADO | AM2: PRESUPUESTO | AN2: PRESUPUESTO | AO2: PRESUPUESTO | AP2: PRESUPUESTO | AQ2: PRESUPUESTO | AR2: PRESUPUESTO | AS2: PRESUPUESTO | AT2: PRESUPUESTO | AU2: PRESUPUESTO | AV2: PRESUPUESTO | AW2: PRESUPUESTO | AX2: PRESUPUESTO | BA2: ANÁLISIS VERTICAL | BB2: ANÁLISIS VERTICAL
D3: =EEFFun!P2 -> 12 | E3: =EEFFun!Q2 -> 1 | F3: =EEFFun!R2 -> 2 | G3: =EEFFun!S2 -> 3 | H3: =EEFFun!T2 -> 4 | I3: 5 | J3: 6 | K3: 7 | L3: 8 | M3: 9 | N3: 10 | O3: 11 | P3: 12 | Q3: 1 | R3: 2 | S3: 3 | T3: 4 | U3: 5 | V3: 6 | W3: 7 | X3: 8 | Y3: 0 | Z3: 10 | AA3: 11 | AB3: 12 | AC3: 1 | AD3: 2 | AE3: 3 | AF3: 4 | AG3: 5 | AH3: 6 | AI3: 7 | AJ3: 8 | AK3: 9 | AL3: 10 | AM3: 1 | AN3: 2 | AO3: 3 | AP3: 4 | AQ3: 5 | AR3: 6 | AS3: 7 | AT3: 8 | AU3: 9 | AV3: 10 | AW3: 11 | AX3: 12 | AY3: 202406-202412 | AZ3: 202312-202412 | BA3: 2023 | BB3: 2024
A4: D | B4: BALANCE GENERAL - PRESUPUESTO MENSUAL | D4: =EEFFun!P3 -> 44926 | E4: =EEFFun!Q3 -> 44957 | F4: =EEFFun!R3 -> 44985 | G4: =EEFFun!S3 -> 45016 | H4: =EEFFun!T3 -> 45046 | I4: =EEFFun!U3 -> 45077 | J4: =EEFFun!V3 -> 45107 | K4: =EEFFun!W3 -> 45138 | ... AB4: =EEFFun!AN3 -> 45657 | AC4: 2025-1 | AD4: 2025-2 | AE4: 2025-3 | AF4: 2025-4 | AG4: 2025-5 | AH4: 2025-6 | AI4: 2025-7 | AJ4: 2025-8 | AK4: 2025-9 | AL4: 2025-10 | AM4: 45688 | AN4: 45716 | AO4: 45747 | AP4: 45777 | AQ4: 45808 | AR4: 45838 | AS4: 45869 | AT4: 45900 | AU4: 45930 | AV4: 45961 | AW4: 45991 | AX4: 46022 | AY4: Comportam | AZ4: Comportam | BA4: % | BB4: %
A5: 1 | B5: =EEFFun!B4 -> 1 | C5: =EEFFun!C4 -> ACTIVOS | D5: =EEFFun!P4 -> 41871995 | E5: =EEFFun!Q4 -> 41428485 | F5: =EEFFun!R4 -> 41342572 | G5: =EEFFun!S4 -> 41608837 | H5: =EEFFun!T4 -> 41402927 | I5: =EEFFun!U4 -> 40814797 | J5: =EEFFun!V4 -> 39918747 | K5: =EEFFun!W4 -> 38859684 | ... AL5: =EEFFun!AX4 -> 72243574 | AM5: =AM6+AM20+AM39+AM102+AM112+AM122+AM134 -> 76988041 | AN5: =AN6+AN20+AN39+AN102+AN112+AN122+AN134 -> 82087921 | AO5: =AO6+AO20+AO39+AO102+AO112+AO122+AO134 -> 87307824 | AP5: =AP6+AP20+AP39+AP102+AP112+AP122+AP134 -> 92258595 | AQ5: =AQ6+AQ20+AQ39+AQ102+AQ112+AQ122+AQ134 -> 97129483 | AR5: =AR6+AR20+AR39+AR102+AR112+AR122+AR134 -> 1.022545e+08 | AS5: =AS6+AS20+AS39+AS102+AS112+AS122+AS134 -> 1.0838113e+08 | AT5: =AT6+AT20+AT39+AT102+AT112+AT122+AT134 -> 1.1345952e+08 | ... AX5: =AX6+AX20+AX39+AX102+AX112+AX122+AX134 -> 1.3374238e+08 | AY5: =AX5-V5 -> 86679839 | AZ5: =AX5-P5 -> 95578761 | BA5: =BA6+BA20+BA39+BA102+BA112+BA122+BA134 -> 1 | BB5: =BB6+BB20+BB39+BB102+BB112+BB122+BB134 -> 1 | BC5: =AT5-W5 -> 66346180
A6: 2 | B6: =EEFFun!B5 -> 11 | C6: =EEFFun!C5 -> FONDOS DISPONIBLES | D6: =EEFFun!P5 -> 1875049.3 | E6: =EEFFun!Q5 -> 2157721.8 | F6: =EEFFun!R5 -> 1067075.5 | G6: =EEFFun!S5 -> 1371077.2 | H6: =EEFFun!T5 -> 1367417.2 | I6: =EEFFun!U5 -> 639585.39 | J6: =EEFFun!V5 -> 1015149.9 | K6: =EEFFun!W5 -> 1439298.4 | ... AL6: =EEFFun!AX5 -> 4340169 | AM6: =AM7+AM12+AM14+AM17 -> 4832852.9 | AN6: =AN7+AN12+AN14+AN17 -> 5768827.1 | AO6: =AO7+AO12+AO14+AO17 -> 5905297.6 | AP6: =AP7+AP12+AP14+AP17 -> 5932709.8 | AQ6: =AQ7+AQ12+AQ14+AQ17 -> 6786992.6 | AR6: =AR7+AR12+AR14+AR17 -> 6451153.8 | AS6: =AS7+AS12+AS14+AS17 -> 6515681.2 | AT6: =AT7+AT12+AT14+AT17 -> 6227035.7 | ... AX6: =AX7+AX12+AX14+AX17 -> 8116267.4 | AY6: =AX6-V6 -> 3861730.8 | AZ6: =AX6-P6 -> 6085400.3 | BA6: =P6/$P$5 -> 0.053214742 | BB6: =AX6/$AX$5 -> 0.060685831 | BC6: =AT6-W6 -> 2127739.7
A7: 4 | B7: =EEFFun!B6 -> 1101 | C7: =EEFFun!C6 -> Caja | D7: =EEFFun!P6 -> 214026.13 | E7: =EEFFun!Q6 -> 277847.72 | F7: =EEFFun!R6 -> 286876.51 | G7: =EEFFun!S6 -> 204150.86 | H7: =EEFFun!T6 -> 160152.06 | I7: =EEFFun!U6 -> 131044.46 | J7: =EEFFun!V6 -> 176055.54 | K7: =EEFFun!W6 -> 198561.99 | ... AL7: =EEFFun!AX6 -> 163888.03 | AM7: =AM8+AM11 -> 245580.43 | AN7: =AN8+AN11 -> 240150.73 | AO7: =AO8+AO11 -> 240117.8 | AP7: =AP8+AP11 -> 239530.73 | AQ7: =AQ8+AQ11 -> 241889.72 | AR7: =AR8+AR11 -> 242864.75 | AS7: =AS8+AS11 -> 239774.44 | AT7: =AT8+AT11 -> 237796.84 | ... AX7: =AX8+AX11 -> 238504.6 | AY7: =AX7-V7 -> -72346.942 | AZ7: =AX7-P7 -> 30339.698 | BA7: =P7/$P$5 -> 0.0054545379 | BB7: =AX7/$AX$5 -> 0.0017833136 | BC7: =AT7-W7 -> -45484.825
A8: 6 | B8: =EEFFun!B7 -> 110105 | C8: =EEFFun!C7 -> Efectivo | D8: =EEFFun!P7 -> 213326.13 | E8: =EEFFun!Q7 -> 277147.72 | F8: =EEFFun!R7 -> 286476.51 | G8: =EEFFun!S7 -> 203550.86 | H8: =EEFFun!T7 -> 159552.06 | I8: =EEFFun!U7 -> 130444.46 | J8: =EEFFun!V7 -> 175455.54 | K8: =EEFFun!W7 -> 197961.99 | ... AL8: =EEFFun!AX7 -> 163238.03 | AM8: =SUM(AM9:AM10) -> 244980.43 | AN8: =SUM(AN9:AN10) -> 239550.73 | AO8: =SUM(AO9:AO10) -> 239517.8 | AP8: =SUM(AP9:AP10) -> 238930.73 | AQ8: =SUM(AQ9:AQ10) -> 241289.72 | AR8: =SUM(AR9:AR10) -> 242264.75 | AS8: =SUM(AS9:AS10) -> 239174.44 | AT8: =SUM(AT9:AT10) -> 237196.84 | ... AX8: =SUM(AX9:AX10) -> 237854.6 | AY8: =AX8-V8 -> -72396.942 | AZ8: =AX8-P8 -> 30289.698 | BA8: =P8/$P$5 -> 0.0054388161 | BB8: =AX8/$AX$5 -> 0.0017784535 | BC8: =AT8-W8 -> -45484.825
A9: 8 | B9: =EEFFun!B8 -> 11010505 | C9: =EEFFun!C8 -> EFECTIVO CAJEROS | D9: =EEFFun!P8 -> 213326.13 | E9: =EEFFun!Q8 -> 277147.72 | F9: =EEFFun!R8 -> 286476.51 | G9: =EEFFun!S8 -> 203550.86 | H9: =EEFFun!T8 -> 159552.06 | I9: =EEFFun!U8 -> 130444.46 | J9: =EEFFun!V8 -> 175455.54 | K9: =EEFFun!W8 -> 197961.99 | ... AL9: =EEFFun!AX8 -> 163238.03 | AM9: =AVERAGE(Q9:AB9) -> 244980.43 | AN9: =AVERAGE(R9:AM9) -> 239550.73 | AO9: =AVERAGE(S9:AN9) -> 239517.8 | AP9: =AVERAGE(T9:AO9) -> 238930.73 | AQ9: =AVERAGE(U9:AP9) -> 241289.72 | AR9: =AVERAGE(V9:AQ9) -> 242264.75 | AS9: =AVERAGE(W9:AR9) -> 239174.44 | AT9: =AVERAGE(X9:AS9) -> 237196.84 | AU9: =AVERAGE(Y9:AT9) -> 238937.84 | ... AX9: =AVERAGE(AB9:AW9) -> 237854.6 | AY9: =AX9-V9 -> -72396.942 | AZ9: =AX9-P9 -> 30289.698 | BA9: =P9/$P$5 -> 0.0054388161 | BB9: =AX9/$AX$5 -> 0.0017784535 | BC9: =AT9-W9 -> -45484.825
A10: 8 | B10: =EEFFun!B9 -> 11010510 | C10: =EEFFun!C9 -> EFECTIVO SERVIPAGOS | D10: =EEFFun!P9 -> 0 | E10: =EEFFun!Q9 -> 0 | F10: =EEFFun!R9 -> 0 | G10: =EEFFun!S9 -> 0 | H10: =EEFFun!T9 -> 0 | I10: =EEFFun!U9 -> 0 | J10: =EEFFun!V9 -> 0 | K10: =EEFFun!W9 -> 0 | ... AL10: =EEFFun!AX9 -> 0 | AM10: =Q10 -> 0 | AN10: =R10 -> 0 | AO10: =S10 -> 0 | AP10: =T10 -> 0 | AQ10: =U10 -> 0 | AR10: =V10 -> 0 | AS10: =W10 -> 0 | AT10: =X10 -> 0 | ... AX10: =AB10 -> 0 | AY10: =AX10-V10 -> 0 | AZ10: =AX10-P10 -> 0 | BA10: =P10/$P$5 -> 0 | BB10: =AX10/$AX$5 -> 0 | BC10: =AT10-W10 -> 0
A11: 6 | B11: =EEFFun!B10 -> 110110 | C11: =EEFFun!C10 -> Caja chica | D11: =EEFFun!P10 -> 700 | E11: =EEFFun!Q10 -> 700 | F11: =EEFFun!R10 -> 400 | G11: =EEFFun!S10 -> 600 | H11: =EEFFun!T10 -> 600 | I11: =EEFFun!U10 -> 600 | J11: =EEFFun!V10 -> 600 | K11: =EEFFun!W10 -> 600 | ... AL11: =EEFFun!AX10 -> 650 | AM11: =Q11 -> 600 | AN11: =R11 -> 600 | AO11: =S11 -> 600 | AP11: =T11 -> 600 | AQ11: =U11 -> 600 | AR11: =V11 -> 600 | AS11: =W11 -> 600 | AT11: =X11 -> 600 | ... AX11: =AB11 -> 650 | AY11: =AX11-V11 -> 50 | AZ11: =AX11-P11 -> 50 | BA11: =P11/$P$5 -> 1.572178e-05 | BB11: =AX11/$AX$5 -> 4.86009e-06 | BC11: =AT11-W11 -> 0
A12: 4 | B12: =EEFFun!B11 -> 1102 | C12: =EEFFun!C11 -> Depósitos para encaje | D12: =EEFFun!P11 -> 1458459.1 | E12: =EEFFun!Q11 -> 1655874.6 | F12: =EEFFun!R11 -> 696024.36 | G12: =EEFFun!S11 -> 729617.53 | H12: =EEFFun!T11 -> 914088.16 | I12: =EEFFun!U11 -> 395720.74 | J12: =EEFFun!V11 -> 661246.05 | K12: =EEFFun!W11 -> 905886.15 | ... AL12: =EEFFun!AX11 -> 1771523.1 | AM12: =AM13 -> 2311231.9 | AN12: =AN13 -> 3205437.2 | AO12: =AO13 -> 3341132 | AP12: =AP13 -> 3501797.4 | AQ12: =AQ13 -> 4287844.4 | AR12: =AR13 -> 3888320.4 | AS12: =AS13 -> 3929571.3 | AT12: =AT13 -> 3769054.6 | ... AX12: =AX13 -> 5593793.8 | AY12: =AX12-V12 -> 2450042.8 | AZ12: =AX12-P12 -> 4188047 | BA12: =P12/$P$5 -> 0.036834735 | BB12: =AX12/$AX$5 -> 0.041825141 | BC12: =AT12-W12 -> 962550.58
A13: 6 | B13: =EEFFun!B12 -> 110205 | C13: =EEFFun!C12 -> Banco Central del Ecuador | D13: =EEFFun!P12 -> 1458459.1 | E13: =EEFFun!Q12 -> 1655874.6 | F13: =EEFFun!R12 -> 696024.36 | G13: =EEFFun!S12 -> 729617.53 | H13: =EEFFun!T12 -> 914088.16 | I13: =EEFFun!U12 -> 395720.74 | J13: =EEFFun!V12 -> 661246.05 | K13: =EEFFun!W12 -> 905886.15 | ... AL13: =EEFFun!AX12 -> 1771523.1 | AM13: 2311231.9 | AN13: 3205437.2 | AO13: 3341132 | AP13: 3501797.4 | AQ13: 4287844.4 | AR13: 3888320.4 | AS13: 3929571.3 | AT13: 3769054.6 | AU13: 3827145.9 | AV13: 4040969.4 | AW13: 4924504.9 | AX13: 5593793.8 | AY13: =AX13-V13 -> 2450042.8 | AZ13: =AX13-P13 -> 4188047 | BA13: =P13/$P$5 -> 0.036834735 | BB13: =AX13/$AX$5 -> 0.041825141 | BC13: =AT13-W13 -> 962550.58
A14: 4 | B14: =EEFFun!B13 -> 1103 | C14: =EEFFun!C13 -> Bancos y otras instituciones financieras | D14: =EEFFun!P13 -> 158169.61 | E14: =EEFFun!Q13 -> 195182.12 | F14: =EEFFun!R13 -> 71708.75 | G14: =EEFFun!S13 -> 422965.87 | H14: =EEFFun!T13 -> 281591.29 | I14: =EEFFun!U13 -> 98347.3 | J14: =EEFFun!V13 -> 169766.14 | K14: =EEFFun!W13 -> 318895.57 | ... AL14: =EEFFun!AX13 -> 2378842.1 | AM14: =SUM(AM15:AM16) -> 2258922.5 | AN14: =SUM(AN15:AN16) -> 2278578.4 | AO14: =SUM(AO15:AO16) -> 2280062.1 | AP14: =SUM(AP15:AP16) -> 2145955.8 | AQ14: =SUM(AQ15:AQ16) -> 2210156.5 | AR14: =SUM(AR15:AR16) -> 2272108.6 | AS14: =SUM(AS15:AS16) -> 2297209.1 | AT14: =SUM(AT15:AT16) -> 2168933 | ... AX14: =SUM(AX15:AX16) -> 2224130.3 | AY14: =AX14-V14 -> 1444196.2 | AZ14: =AX14-P14 -> 1980081.3 | BA14: =P14/$P$5 -> 0.006394808 | BB14: =AX14/$AX$5 -> 0.016629959 | BC14: =AT14-W14 -> 1161801.8
A15: 6 | B15: =EEFFun!B14 -> 110310 | C15: =EEFFun!C14 -> Bancos e instituciones financieras locales | D15: =EEFFun!P14 -> 149402.61 | E15: =EEFFun!Q14 -> 186391.8 | F15: =EEFFun!R14 -> 62918.43 | G15: =EEFFun!S14 -> 414175.55 | H15: =EEFFun!T14 -> 272800.97 | I15: =EEFFun!U14 -> 89556.98 | J15: =EEFFun!V14 -> 160975.82 | K15: =EEFFun!W14 -> 310105.25 | ... AL15: =EEFFun!AX14 -> 2369967.9 | AM15: =AVERAGE(AC15:AL15) -> 2250048.3 | AN15: =AVERAGE(AD15:AM15) -> 2269704.2 | AO15: =AVERAGE(AE15:AN15) -> 2271187.9 | AP15: =AVERAGE(AF15:AO15) -> 2137081.6 | AQ15: =AVERAGE(AG15:AP15) -> 2201282.2 | AR15: =AVERAGE(AH15:AQ15) -> 2263234.3 | AS15: =AVERAGE(AI15:AR15) -> 2288334.8 | AT15: =AVERAGE(AJ15:AS15) -> 2160058.7 | ... AX15: =AVERAGE(AN15:AW15) -> 2215256 | AY15: =AX15-V15 -> 1444196.2 | AZ15: =AX15-P15 -> 1980081.3 | BA15: =P15/$P$5 -> 0.0061622756 | BB15: =AX15/$AX$5 -> 0.016563605 | BC15: =AT15-W15 -> 1161801.8
A16: 6 | B16: =EEFFun!B15 -> 110315 | C16: =EEFFun!C15 -> Bancos e instituciones financieras del exterior | D16: =EEFFun!P15 -> 8767 | E16: =EEFFun!Q15 -> 8790.32 | F16: =EEFFun!R15 -> 8790.32 | G16: =EEFFun!S15 -> 8790.32 | H16: =EEFFun!T15 -> 8790.32 | I16: =EEFFun!U15 -> 8790.32 | J16: =EEFFun!V15 -> 8790.32 | K16: =EEFFun!W15 -> 8790.32 | ... AL16: =EEFFun!AX15 -> 8874.28 | AM16: =Q16 -> 8874.28 | AN16: =R16 -> 8874.28 | AO16: =S16 -> 8874.28 | AP16: =T16 -> 8874.28 | AQ16: =U16 -> 8874.28 | AR16: =V16 -> 8874.28 | AS16: =W16 -> 8874.28 | AT16: =X16 -> 8874.28 | ... AX16: =AB16 -> 8874.28 | AY16: =AX16-V16 -> 0 | AZ16: =AX16-P16 -> 0 | BA16: =P16/$P$5 -> 0.00023253246 | BB16: =AX16/$AX$5 -> 6.6353538e-05 | BC16: =AT16-W16 -> 0
A17: 4 | B17: =EEFFun!B16 -> 1104 | C17: =EEFFun!C16 -> Efectos de cobro inmediato | D17: =EEFFun!P16 -> 44394.42 | E17: =EEFFun!Q16 -> 28817.37 | F17: =EEFFun!R16 -> 12465.85 | G17: =EEFFun!S16 -> 14342.96 | H17: =EEFFun!T16 -> 11585.67 | I17: =EEFFun!U16 -> 14472.89 | J17: =EEFFun!V16 -> 8082.17 | K17: =EEFFun!W16 -> 15954.67 | ... AL17: =EEFFun!AX16 -> 25915.8 | AM17: =AM18+AM19 -> 17117.974 | AN17: =AN18+AN19 -> 44660.699 | AO17: =AO18+AO19 -> 43985.572 | AP17: =AP18+AP19 -> 45425.825 | AQ17: =AQ18+AQ19 -> 47101.999 | AR17: =AR18+AR19 -> 47860.062 | AS17: =AS18+AS19 -> 49126.429 | AT17: =AT18+AT19 -> 51251.305 | ... AX17: =AX18+AX19 -> 59838.733 | AY17: =AX17-V17 -> 39838.733 | AZ17: =AX17-P17 -> -113067.7 | BA17: =P17/$P$5 -> 0.0045306614 | BB17: =AX17/$AX$5 -> 0.00044741789 | BC17: =AT17-W17 -> 48872.155
A18: 6 | B18: =EEFFun!B17 -> 110405 | C18: =EEFFun!C17 -> EFECTOS INGRESADOS A CAJA | D18: =EEFFun!P17 -> 0 | E18: =EEFFun!Q17 -> 0 | F18: =EEFFun!R17 -> 0 | G18: =EEFFun!S17 -> 0 | H18: =EEFFun!T17 -> 0 | I18: =EEFFun!U17 -> 0 | J18: =EEFFun!V17 -> 0 | K18: =EEFFun!W17 -> 0 | ... AL18: =EEFFun!AX17 -> 0 | AY18: =AX18-V18 -> 0 | AZ18: =AX18-P18 -> 0 | BA18: =P18/$P$5 -> 0 | BB18: =AX18/$AX$5 -> 0 | BC18: =AT18-W18 -> 0
A19: 6 | B19: =EEFFun!B18 -> 110410 | C19: =EEFFun!C18 -> VALORES ENVIADOS A CÁMARA DE COMPENSACIÓN | D19: =EEFFun!P18 -> 44394.42 | E19: =EEFFun!Q18 -> 28817.37 | F19: =EEFFun!R18 -> 12465.85 | G19: =EEFFun!S18 -> 14342.96 | H19: =EEFFun!T18 -> 11585.67 | I19: =EEFFun!U18 -> 14472.89 | J19: =EEFFun!V18 -> 8082.17 | K19: =EEFFun!W18 -> 15954.67 | ... AL19: =EEFFun!AX18 -> 25915.8 | AM19: =AVERAGE(Q19:AB19) -> 17117.974 | AN19: =AVERAGE(R19:AM19) -> 44660.699 | AO19: =AVERAGE(S19:AN19) -> 43985.572 | AP19: =AVERAGE(T19:AO19) -> 45425.825 | AQ19: =AVERAGE(U19:AP19) -> 47101.999 | AR19: =AVERAGE(V19:AQ19) -> 47860.062 | AS19: =AVERAGE(W19:AR19) -> 49126.429 | AT19: =AVERAGE(X19:AS19) -> 51251.305 | AU19: =AVERAGE(Y19:AT19) -> 53563.179 | ... AX19: =AVERAGE(AB19:AW19) -> 59838.733 | AY19: =AX19-V19 -> 39838.733 | AZ19: =AX19-P19 -> -113067.7 | BA19: =P19/$P$5 -> 0.0045306614 | BB19: =AX19/$AX$5 -> 0.00044741789 | BC19: =AT19-W19 -> 48872.155
A20: 2 | B20: =EEFFun!B19 -> 13 | C20: =EEFFun!C19 -> INVERSIONES | D20: =EEFFun!P19 -> 4569816.5 | E20: =EEFFun!Q19 -> 4396213.9 | F20: =EEFFun!R19 -> 4304281.3 | G20: =EEFFun!S19 -> 3882342.1 | H20: =EEFFun!T19 -> 3717634.7 | I20: =EEFFun!U19 -> 3705733.6 | J20: =EEFFun!V19 -> 3355464.7 | K20: =EEFFun!W19 -> 2765240.9 | ... AL20: =EEFFun!AX19 -> 6909362.7 | AM20: =AM21+AM27+AM32+AM35+AM37 -> 6212324.5 | AN20: =AN21+AN27+AN32+AN35+AN37 -> 5602025.5 | AO20: =AO21+AO27+AO32+AO35+AO37 -> 6026932.9 | AP20: =AP21+AP27+AP32+AP35+AP37 -> 6838671.8 | AQ20: =AQ21+AQ27+AQ32+AQ35+AQ37 -> 6223039 | AR20: =AR21+AR27+AR32+AR35+AR37 -> 7237293.6 | AS20: =AS21+AS27+AS32+AS35+AS37 -> 8925517.5 | AT20: =AT21+AT27+AT32+AT35+AT37 -> 9941448.2 | ... AX20: =AX21+AX27+AX32+AX35+AX37 -> 11119798 | AY20: =AX20-V20 -> 4216831.2 | AZ20: =AX20-P20 -> 5646839 | BA20: =P20/$P$5 -> 0.14340777 | BB20: =AX20/$AX$5 -> 0.083143417 | BC20: =AT20-W20 -> 3447191.8
A21: 4 | B21: =EEFFun!B20 -> 1303 | C21: =EEFFun!C20 -> Disponibles para la venta de entidades del sector privado | D21: =EEFFun!P20 -> 873535.46 | E21: =EEFFun!Q20 -> 675506.01 | F21: =EEFFun!R20 -> 571537.73 | G21: =EEFFun!S20 -> 159326.22 | H21: =EEFFun!T20 -> 0 | I21: =EEFFun!U20 -> 0 | J21: =EEFFun!V20 -> 0 | K21: =EEFFun!W20 -> 0 | ... AL21: =EEFFun!AX20 -> 1333972.4 | AM21: =SUM(AM22:AM26) -> 1290464.2 | AN21: =SUM(AN22:AN26) -> 2617206.1 | AO21: =SUM(AO22:AO26) -> 2476803.7 | AP21: =SUM(AP22:AP26) -> 3719868 | AQ21: =SUM(AQ22:AQ26) -> 3641540.7 | AR21: =SUM(AR22:AR26) -> 4160715.2 | AS21: =SUM(AS22:AS26) -> 4024862.3 | AT21: =SUM(AT22:AT26) -> 6133715.4 | ... AX21: =SUM(AX22:AX26) -> 6434978.9 | AY21: =AX21-V21 -> 2933116.8 | AZ21: =AX21-P21 -> 3141490.9 | BA21: =P21/$P$5 -> 0.086299155 | BB21: =AX21/$AX$5 -> 0.048114733 | BC21: =AT21-W21 -> 3203087.7
A22: 6 | B22: =EEFFun!B21 -> 130305 | C22: =EEFFun!C21 -> De 1 a 30 días | D22: =EEFFun!P21 -> 202034.17 | E22: =EEFFun!Q21 -> 107021.85 | F22: =EEFFun!R21 -> 413146.67 | G22: =EEFFun!S21 -> 159326.22 | H22: =EEFFun!T21 -> 0 | I22: =EEFFun!U21 -> 0 | J22: =EEFFun!V21 -> 0 | K22: =EEFFun!W21 -> 0 | ... AL22: =EEFFun!AX21 -> 823359.35 | AM22: =AC22-INV!B16+INV!C16+900000-200000 -> 880958.11 | AN22: =AD22-INV!C16+INV!D16+600000-200000 -> 938713.65 | AO22: =AE22-INV!D16+INV!E16-500000+700000-200000 -> 1184575.4 | AP22: =AF22-INV!E16+INV!F16+700000-290000 -> 1199389 | AQ22: =AG22-INV!F16+INV!G16+600000-490000 -> 946215.76 | AR22: =AH22-INV!G16+INV!H16+400000-760000 -> 407890.25 | AS22: =AI22-INV!H16+INV!I16 -> 393345.64 | AT22: =AJ22-INV!I16+INV!J16 -> 1356503.6 | AU22: =AK22-INV!J16+INV!K16+600000 -> 2021996.4 | AV22: =AL22-INV!K16+INV!L16+1000000 -> 1823359.4 | AW22: =AM22-INV!L16+INV!M16 -> 880958.11 | AX22: =AN22-INV!M16+INV!N16 -> 938713.65 | AY22: =AX22-V22 -> 389605.53 | AZ22: =AX22-P22 -> 845684.48 | BA22: =P22/$P$5 -> 0.0024376402 | BB22: =AX22/$AX$5 -> 0.0070188198 | BC22: =AT22-W22 -> 1356503.6
A23: 6 | B23: =EEFFun!B22 -> 130310 | C23: =EEFFun!C22 -> De 31 a 90 días | D23: =EEFFun!P22 -> 514890.08 | E23: =EEFFun!Q22 -> 568484.16 | F23: =EEFFun!R22 -> 158391.06 | G23: =EEFFun!S22 -> 0 | H23: =EEFFun!T22 -> 0 | I23: =EEFFun!U22 -> 0 | J23: =EEFFun!V22 -> 0 | K23: =EEFFun!W22 -> 0 | ... AL23: =EEFFun!AX22 -> 0 | AM23: =AC23-INV!B17+INV!C17 -> 0 | AN23: =R23-INV!C16+INV!D16+INV!$N$16/12 -> 93446.72 | AO23: =S23-INV!D16+INV!E16+INV!$N$16/12 -> 145324.17 | AP23: =T23-INV!E16+INV!F16+INV!$N$16/12 -> 389401.73 | AQ23: =U23-INV!F16+INV!G16+INV!$N$16/12 -> 545416.85 | AR23: =V23-INV!G16+INV!H16+INV!$N$16/12+800000 -> 844624.19 | AS23: =W23-INV!H16+INV!I16+INV!$N$16/12+800000 -> 937818.79 | AT23: 1865632 | AU23: 2535411 | AV23: =3221436-800000 -> 2421436 | AW23: =3811625-2000000 -> 1811625 | AX23: =4365877-1000000-2000000 -> 1365877 | AY23: =AX23-V23 -> 1321252.8 | AZ23: =AX23-P23 -> 1321401.1 | BA23: =P23/$P$5 -> 0.0011653997 | BB23: =AX23/$AX$5 -> 0.010212746 | BC23: =AT23-W23 -> 1727813.2
A24: 6 | B24: =EEFFun!B23 -> 130315 | C24: =EEFFun!C23 -> De 91 a 180 días | D24: =EEFFun!P23 -> 156611.21 | E24: =EEFFun!Q23 -> 0 | F24: =EEFFun!R23 -> 0 | G24: =EEFFun!S23 -> 0 | H24: =EEFFun!T23 -> 0 | I24: =EEFFun!U23 -> 0 | J24: =EEFFun!V23 -> 0 | K24: =EEFFun!W23 -> 0 | ... AL24: =EEFFun!AX23 -> 0 | AM24: =AC24-INV!B18+INV!C18 -> 0 | AN24: =Q24-INV!G16-INV!E16+400000 -> 537670.47 | AO24: =R24-INV!H16-INV!F16 -> 138587.64 | AP24: =S24-INV!I16-INV!G16 -> 138718.81 | AQ24: =T24-INV!J16-INV!H16 -> 137798.26 | AR24: =U24-INV!K16-INV!I16 -> 138778.69 | AS24: =V24-INV!L16-INV!J16 -> 138707.72 | AT24: =W24-INV!M16-INV!K16 -> 137818.79 | AU24: =AT24 -> 137818.79 | AV24: =AU24-INV!M16+INV!K16+600000 -> 737818.79 | AW24: =AV24 -> 737818.79 | AX24: =AW24 -> 737818.79 | AY24: =AX24-V24 -> 599111.07 | AZ24: =AX24-P24 -> 587859.96 | BA24: =P24/$P$5 -> 0.0039293662 | BB24: =AX24/$AX$5 -> 0.0055167165 | BC24: =AT24-W24 -> 0
A25: 6 | B25: =EEFFun!B24 -> 130320 | C25: =EEFFun!C24 -> De 181 a 360 días | D25: =EEFFun!P24 -> 0 | E25: =EEFFun!Q24 -> 0 | F25: =EEFFun!R24 -> 0 | G25: =EEFFun!S24 -> 0 | H25: =EEFFun!T24 -> 0 | I25: =EEFFun!U24 -> 0 | J25: =EEFFun!V24 -> 0 | K25: =EEFFun!W24 -> 0 | ... AL25: =EEFFun!AX24 -> 0 | AM25: =AC25-INV!B19+INV!C19 -> 275659.74 | AN25: =R25+INV!$N$16/12 -> 277175.29 | AO25: =S25+INV!$N$16/12 -> 277437.62 | AP25: =T25+INV!$N$16/12 -> 275596.52 | AQ25: =U25+INV!$N$16/12 -> 277557.38 | AR25: =V25+INV!$N$16/12 -> 277415.43 | AS25: =W25+INV!$N$16/12 -> 275637.57 | AT25: =X25+INV!$N$16/12 -> 277598.41 | AU25: =Y25+INV!$N$16/12+500000 -> 777461.81 | AV25: =Z25+INV!$N$16/12+600000 -> 875649.22 | AW25: =AA25+INV!$N$16/12 -> 277552.97 | AX25: =AB25+INV!$N$16/12+900000 -> 1177478.7 | AY25: =AX25-V25 -> 900063.25 | AZ25: =AX25-P25 -> 914922.36 | BA25: =P25/$P$5 -> 0.0068797544 | BB25: =AX25/$AX$5 -> 0.0088040806 | BC25: =AT25-W25 -> 1960.84
A26: 6 | B26: =EEFFun!B25 -> 130325 | C26: =EEFFun!C25 -> De más de 360 días | D26: =EEFFun!P25 -> 0 | E26: =EEFFun!Q25 -> 0 | F26: =EEFFun!R25 -> 0 | G26: =EEFFun!S25 -> 0 | H26: =EEFFun!T25 -> 0 | I26: =EEFFun!U25 -> 0 | J26: =EEFFun!V25 -> 0 | K26: =EEFFun!W25 -> 0 | ... AL26: =EEFFun!AX25 -> 0 | AM26: =AC26-INV!B20+INV!C20-1400000-570000 -> 133846.34 | AN26: =R26-INV!$N$16/12-INV!C17-1900000 -> 770199.93 | AO26: =S26-INV!$N$16/12-INV!D17-1900000 -> 730878.84 | AP26: =T26-INV!$N$16/12-INV!E17-1800000+1000000 -> 1716762 | AQ26: =U26-INV!$N$16/12-INV!F17-1800000+1000000 -> 1734552.4 | AR26: =V26-INV!$N$16/12-INV!G17 -> 2492006.6 | AS26: =W26-INV!$N$16/12-INV!H17+1000000-1100000 -> 2279352.6 | AT26: =X26-INV!$N$16/12-INV!I17+1500000-600000 -> 2496162.7 | AU26: =Y26-INV!$N$16/12-INV!J17 -> 1553721.6 | AV26: =Z26-INV!$N$16/12-INV!K17+1000000 -> 3241608.2 | AW26: =AA26-INV!$N$16/12-INV!L17 -> 2256966.2 | AX26: =AB26-INV!$N$16/12-INV!M17 -> 2215090.7 | AY26: =AX26-V26 -> -276915.86 | AZ26: =AX26-P26 -> -528377.06 | BA26: =P26/$P$5 -> 0.071886995 | BB26: =AX26/$AX$5 -> 0.01656237 | BC26: =AT26-W26 -> 116810.05
A27: 4 | B27: =EEFFun!B26 -> 1304 | C27: =EEFFun!C26 -> Disponibles para la venta del estado o de entidades sector público | D27: =EEFFun!P26 -> 1195356.7 | E27: =EEFFun!Q26 -> 1198541.3 | F27: =EEFFun!R26 -> 1201417.8 | G27: =EEFFun!S26 -> 1204602.4 | H27: =EEFFun!T26 -> 1207684.3 | I27: =EEFFun!U26 -> 1210868.9 | J27: =EEFFun!V26 -> 892037.29 | K27: =EEFFun!W26 -> 332131.87 | ... AL27: =EEFFun!AX26 -> 2050883.4 | AM27: =SUM(AM28:AM31) -> 1543183.9 | AN27: =SUM(AN28:AN31) -> 1543770.5 | AO27: =SUM(AO28:AO31) -> 2544918.5 | AP27: =SUM(AP28:AP31) -> 2492200.7 | AQ27: =SUM(AQ28:AQ31) -> 2292858.9 | AR27: =SUM(AR28:AR31) -> 1694604.5 | AS27: =SUM(AS28:AS31) -> 2050971.1 | AT27: =SUM(AT28:AT31) -> 2352904.2 | ... AX27: =SUM(AX28:AX31) -> 3243770.5 | AY27: =AX27-V27 -> 2000647.4 | AZ27: =AX27-P27 -> 3124263.8 | BA27: =P27/$P$5 -> 0.00313143 | BB27: =AX27/$AX$5 -> 0.024253872 | BC27: =AT27-W27 -> 1108950.9
A28: 6 | B28: =EEFFun!B27 -> 130405 | C28: =EEFFun!C27 -> De 1 a 30 días | D28: =EEFFun!P27 -> 0 | E28: =EEFFun!Q27 -> 0 | F28: =EEFFun!R27 -> 0 | G28: =EEFFun!S27 -> 0 | H28: =EEFFun!T27 -> 0 | I28: =EEFFun!U27 -> 0 | J28: =EEFFun!V27 -> 0 | K28: =EEFFun!W27 -> 0 | ... AL28: =EEFFun!AX27 -> 401046.15 | AM28: =AC28-INV!B22+INV!C22 -> 401072.72 | AN28: =AD28-INV!C22+INV!D22 -> 284743.29 | AO28: =AE28-INV!D22+INV!E22 -> 861728.33 | AP28: =AF28-INV!E22+INV!F22 -> 401013.1 | AQ28: =AG28-INV!F22+INV!G22+500000 -> 784688.81 | AR28: =AH28-INV!G22+INV!H22 -> 1011504.5 | AS28: =AI28-INV!H22+INV!I22+1000000 -> 1401015.3 | AT28: =AJ28-INV!I22+INV!J22+1500000 -> 1784715.8 | AU28: =AK28-INV!J22+INV!K22 -> 1171879.3 | AV28: =AL28-INV!K22+INV!L22 -> 401046.15 | AW28: =AM28-INV!L22+INV!M22+2000000-500000 -> 1901072.7 | AX28: =AN28-INV!M22+INV!N22+2500000-1000000 -> 1784743.3 | AY28: =AX28-V28 -> 1504912.8 | AZ28: =AX28-P28 -> 1784743.3 | BA28: =P28/$P$5 -> 0 | BB28: =AX28/$AX$5 -> 0.013344635 | BC28: =AT28-W28 -> 1483881.1
A29: 6 | B29: =EEFFun!B28 -> 130410 | C29: =EEFFun!C28 -> De 31 a 90 días | D29: =EEFFun!P28 -> 0 | E29: =EEFFun!Q28 -> 0 | F29: =EEFFun!R28 -> 0 | G29: =EEFFun!S28 -> 0 | H29: =EEFFun!T28 -> 0 | I29: =EEFFun!U28 -> 0 | J29: =EEFFun!V28 -> 0 | K29: =EEFFun!W28 -> 109225.67 | ... AL29: =EEFFun!AX28 -> 1649837.3 | AM29: =AC29-INV!B23+INV!C23 -> 1142111.2 | AN29: =AD29-INV!C23+INV!D23 -> 1259027.2 | AO29: =AE29-INV!D23+INV!E23+1000000 -> 1683190.2 | AP29: =AF29-INV!E23+INV!F23+1000000 -> 2091187.6 | AQ29: =AG29-INV!F23+INV!G23+100000 -> 1508170.1 | AR29: =AH29-INV!G23+INV!H23 -> 683100 | AS29: =AI29-INV!H23+INV!I23-800000 -> 649955.85 | AT29: =AJ29-INV!I23+INV!J23-1000000 -> 568188.4 | AU29: =AK29-INV!J23+INV!K23 -> 782904.38 | AV29: =AL29-INV!K23+INV!L23-1000000 -> 649837.29 | AW29: =AM29-INV!L23+INV!M23 -> 1142111.2 | AX29: =AN29-INV!M23+INV!N23+2000000-1800000 -> 1459027.2 | AY29: =AX29-V29 -> 495734.6 | AZ29: =AX29-P29 -> 1339520.5 | BA29: =P29/$P$5 -> 0.00313143 | BB29: =AX29/$AX$5 -> 0.010909236 | BC29: =AT29-W29 -> -374930.22
A30: 6 | B30: =EEFFun!B29 -> 130415 | C30: =EEFFun!C29 -> De 91 a 180 días | D30: =EEFFun!P29 -> 0 | E30: =EEFFun!Q29 -> 0 | F30: =EEFFun!R29 -> 0 | G30: =EEFFun!S29 -> 0 | H30: =EEFFun!T29 -> 459793.53 | I30: =EEFFun!U29 -> 1004114.3 | J30: =EEFFun!V29 -> 892037.29 | K30: =EEFFun!W29 -> 222906.2 | ... AL30: =EEFFun!AX29 -> 0 | AM30: =AC30-INV!B24+INV!C24 -> 0 | AN30: =AD30-INV!C24+INV!D24 -> 0 | AO30: =AE30-INV!D24+INV!E24 -> 0 | AP30: =AF30-INV!E24+INV!F24 -> 0 | AQ30: =AG30-INV!F24+INV!G24 -> 0 | AR30: =AH30-INV!G24+INV!H24 -> 0 | AS30: =AI30-INV!H24+INV!I24 -> 0 | AT30: =AJ30-INV!I24+INV!J24 -> 0 | ... AX30: =AN30-INV!M24+INV!N24 -> 0 | AY30: =AX30-V30 -> 0 | AZ30: =AX30-P30 -> 0 | BA30: =P30/$P$5 -> 0 | BB30: =AX30/$AX$5 -> 0 | BC30: =AT30-W30 -> 0
A31: 6 | B31: =EEFFun!B30 -> 130420 | C31: =EEFFun!C30 -> De 181 a 360 días | D31: =EEFFun!P30 -> 1195356.7 | E31: =EEFFun!Q30 -> 1198541.3 | F31: =EEFFun!R30 -> 1201417.8 | G31: =EEFFun!S30 -> 1204602.4 | H31: =EEFFun!T30 -> 747890.73 | I31: =EEFFun!U30 -> 206754.59 | J31: =EEFFun!V30 -> 0 | K31: =EEFFun!W30 -> 0 | ... AL31: =EEFFun!AX30 -> 0 | AM31: =AC31-INV!B25+INV!C25 -> 0 | AN31: =AD31-INV!C25+INV!D25 -> 0 | AO31: =AE31-INV!D25+INV!E25 -> 0 | AP31: =AF31-INV!E25+INV!F25 -> 0 | AQ31: =AG31-INV!F25+INV!G25 -> 0 | AR31: =AH31-INV!G25+INV!H25 -> 0 | AS31: =AI31-INV!H25+INV!I25 -> 0 | AT31: =AJ31-INV!I25+INV!J25 -> 0 | ... AX31: =AN31-INV!M25+INV!N25 -> 0 | AY31: =AX31-V31 -> 0 | AZ31: =AX31-P31 -> 0 | BA31: =P31/$P$5 -> 0 | BB31: =AX31/$AX$5 -> 0 | BC31: =AT31-W31 -> 0
A32: 4 | B32: =EEFFun!B31 -> 1305 | C32: =EEFFun!C31 -> Mantenidas hasta el vencimiento de entidades sector privado | D32: =EEFFun!P31 -> 0 | E32: =EEFFun!Q31 -> 0 | F32: =EEFFun!R31 -> 0 | G32: =EEFFun!S31 -> 0 | H32: =EEFFun!T31 -> 0 | I32: =EEFFun!U31 -> 0 | J32: =EEFFun!V31 -> 0 | K32: =EEFFun!W31 -> 0 | ... AL32: =EEFFun!AX31 -> 0 | AM32: =AM33+AM34 -> 0 | AN32: =AN33+AN34 -> 0 | AO32: =AO33+AO34 -> 0 | AP32: =AP33+AP34 -> 0 | AQ32: =AQ33+AQ34 -> 0 | AR32: =AR33+AR34 -> 0 | AS32: =AS33+AS34 -> 0 | AT32: =AT33+AT34 -> 0 | ... AX32: =AX33+AX34 -> 0 | AY32: =AX32-V32 -> 0 | AZ32: =AX32-P32 -> 0 | BA32: =P32/$P$5 -> 0 | BB32: =AX32/$AX$5 -> 0 | BC32: =AT32-W32 -> 0
A33: 6 | B33: =EEFFun!B32 -> 130505 | C33: =EEFFun!C32 -> De 1 a 30 días | D33: =EEFFun!P32 -> 0 | E33: =EEFFun!Q32 -> 0 | F33: =EEFFun!R32 -> 0 | G33: =EEFFun!S32 -> 0 | H33: =EEFFun!T32 -> 0 | I33: =EEFFun!U32 -> 0 | J33: =EEFFun!V32 -> 0 | K33: =EEFFun!W32 -> 0 | ... AL33: =EEFFun!AX32 -> 0 | AM33: =AC33-INV!B27+INV!C27 -> 0 | AN33: =AD33-INV!C27+INV!D27 -> 0 | AO33: =AE33-INV!D27+INV!E27 -> 0 | AP33: =AF33-INV!E27+INV!F27 -> 0 | AQ33: =AG33-INV!F27+INV!G27 -> 0 | AR33: =AH33-INV!G27+INV!H27 -> 0 | AS33: =AI33-INV!H27+INV!I27 -> 0 | AT33: =AJ33-INV!I27+INV!J27 -> 0 | ... AX33: =AN33-INV!M27+INV!N27 -> 0 | AY33: =AX33-V33 -> 0 | AZ33: 0 | BA33: =P33/$P$5 -> 0 | BB33: =AX33/$AX$5 -> 0 | BC33: =AT33-W33 -> 0
A34: 6 | B34: =EEFFun!B33 -> 130510 | C34: =EEFFun!C33 -> De 31 a 90 días | D34: =EEFFun!P33 -> 0 | E34: =EEFFun!Q33 -> 0 | F34: =EEFFun!R33 -> 0 | G34: =EEFFun!S33 -> 0 | H34: =EEFFun!T33 -> 0 | I34: =EEFFun!U33 -> 0 | J34: =EEFFun!V33 -> 0 | K34: =EEFFun!W33 -> 0 | ... AL34: =EEFFun!AX33 -> 0 | AM34: =AC34-INV!B28+INV!C28 -> 0 | AN34: =AD34-INV!C28+INV!D28 -> 0 | AO34: =AE34-INV!D28+INV!E28 -> 0 | AP34: =AF34-INV!E28+INV!F28 -> 0 | AQ34: =AG34-INV!F28+INV!G28 -> 0 | AR34: =AH34-INV!G28+INV!H28 -> 0 | AS34: =AI34-INV!H28+INV!I28 -> 0 | AT34: =AJ34-INV!I28+INV!J28 -> 0 | ... AX34: =AN34-INV!M28+INV!N28 -> 0 | AY34: =AX34-V34 -> 0 | AZ34: 0 | BA34: =P34/$P$5 -> 0 | BB34: =AX34/$AX$5 -> 0 | BC34: =AT34-W34 -> 0
